<?xml version="1.0" ?>
<robot name="firstmodel">

  <material name="blue">
    <color rgba="0 0 0.8 1"/>
  </material>

  <material name="white">
    <color rgba="1 1 1 1"/>
  </material>

  <material name="black">
    <color rgba="0 0 0 1"/>
  </material>

  <link name="base_link">
    <visual>
      <geometry>
        <cylinder length="0.6" radius="0.2"/>
      </geometry>
      <material name="blue"/>
    </visual>
  </link>

  <link name="right_leg">
    <visual>
      <geometry>
        <box size="0.6 0.1 0.2"/>
      </geometry>
      <origin rpy="0 1.57075 0" xyx="0 0 -0.3"/>
      <material name="white"/>
    </visual>
  </link>

  <joint name="base_to_right_leg" type="fixed">
    <parent link="base_link"/>
    <child link="right_leg"/>
    <origin xyz="0 -0.22 -0.05"/>
  </joint>

  <link name="left_leg">
    <visual>
      <geometry>
        <box size="0.6 0.1 0.2"/>
      </geometry>
      <origin rpy="0 1.57075 0" xyx="0 0 -0.3"/>
      <material name="white"/>
    </visual>
  </link>

  <joint name="base_to_left_leg" type="fixed">
    <parent link="base_link"/>
    <child link="left_leg"/>
    <origin xyz="0 0.22 -0.05"/>
  </joint>

  <link name="head">
    <visual>
      <geometry>
        <sphere radius="0.2"/>
      </geometry>
      <material name="white"/>
    </visual>
  </link>

  <joint name="base_to_head" type="fixed">
    <parent link="base_link"/>
    <child link="head"/>
    <origin xyz="0 0 0.3"/>
  </joint>

  <link name="camera">
    <visual>
      <geometry>
        <cylinder length="0.005" radius="0.008"/>
      </geometry>
      <origin rpy="0 1.57075 0" xyx="0 0 0"/>
      <material name="black"/>
    </visual>
  </link>

  <joint name="camera_to_head" type="fixed">
    <parent link="head"/>
    <child link="camera"/>
    <origin xyz="0.18 0 0.1"/>
  </joint>

  <link name="left_foot">
    <visual>
      <geometry>
        <box size="0.4 0.1 0.1"/>
      </geometry>
      <material name="white"/>
    </visual>
  </link>

  <joint name="left_leg_to_left_foot" type="fixed">
    <parent link="left_leg"/>
    <child link="left_foot"/>
    <origin xyz="0 0 -0.3"/>
  </joint>

  <link name="right_foot">
    <visual>
      <geometry>
        <box size="0.4 0.1 0.1"/>
      </geometry>
      <material name="white"/>
    </visual>
  </link>

  <joint name="right_leg_to_right_foot" type="fixed">
    <parent link="right_leg"/>
    <child link="right_foot"/>
    <origin xyz="0 0 -0.3"/>
  </joint>

  <link name="bottom_plate">
    <visual>
      <geometry>
        <cylinder length="0.05" radius="0.4"/>
      </geometry>
      <material name="blue"/>
    </visual>
  </link>

  <joint name="right_foot_to_base_bottom_plate" type="fixed">
    <parent link="right_foot"/>
    <child link="bottom_plate"/>
    <origin xyz="0 0.22 -0.06"/>
  </joint>

  <link name="left_wheel">
    <visual>
      <geometry>
        <cylinder length="0.1" radius="0.1"/>
      </geometry>
      <origin rpy="1.57075 0 0" xyx="0 0 0"/>
      <material name="black"/>
    </visual>
  </link>

  <joint name="left_wheel_to_bottom_plate" type="revolute">
    <parent link="bottom_plate"/>
    <child link="left_wheel"/>
    <origin xyz="0 0.40 0"/>
    <axis xyz="0 1 0"/>
    <limit effort="30" lower="-2.617" upper="2.617" velocity="1.571"/>
  </joint>

  <link name="right_wheel">
    <visual>
      <geometry>
        <cylinder length="0.1" radius="0.1"/>
      </geometry>
      <origin rpy="1.57075 0 0" xyz="0 0 0"/>
      <material name="black"/>
    </visual>
  </link>

  <joint name="right_wheel_to_bottom_plate" type="revolute">
    <parent link="bottom_plate"/>
    <child link="right_wheel"/>
    <origin xyz="0 -0.40 0"/>
    <axis xyz="0 1 0"/>
    <limit effort="30" lower="-2.617" upper="2.617" velocity="1.571"/>
  </joint>

  <link name="front_caster">
    <visual>
      <geometry>
        <cylinder length="0.05" radius="0.055"/>
      </geometry>
      <origin rpy="1.57075 1.57075 0" xyz="0 0 0"/>
      <material name="black"/>
    </visual>
  </link>

  <joint name="front_caster_to_bottom_plate" type="fixed">
    <parent link="bottom_plate"/>
    <child link="front_caster"/>
    <origin xyz="0.30 0 -0.03"/>
  </joint>

  <link name="back_caster">
    <visual>
      <geometry>
        <cylinder length="0.05" radius="0.055"/>
      </geometry>
      <origin rpy="1.57075 1.57075 0" xyz="0 0 0"/>
      <material name="black"/>
    </visual>
  </link>

  <joint name="back_caster_to_bottom_plate" type="fixed">
    <parent link="bottom_plate"/>
    <child link="back_caster"/>
    <origin xyz="-0.30 0 -0.03"/>
  </joint>

</robot>
